Workbook
Name NativeTimeline_Order_Date: #N/A
Name Slicer_Category: #N/A
Name Slicer_City: #N/A
Name Slicer_Customer_Status: #N/A
Name Slicer_Payment_Method: #N/A

Sheet Raw_Data
A1: Order_ID | B1: Customer_Name | C1: Email | D1: Phone | E1: City | F1: Product | G1: Category | H1: Order_Date | I1: Quantity | J1: Unit_Price | K1: Total_Sales | L1: Payment_Method | M1: Customer_Status | N1: Delivery_Date
A2: ORD-1001 | B2: Mahnoor Khan | C2: mahnoor.khan@yahoo.com | D2: 0369 2458591 | E2: Lahore | F2: Microwave Oven | H2: 46238 | I2: 2 | J2: 45000 | K2: =I2*J2 -> 90000 | L2: Cash | N2: 46243
A3: ORD-1002 | B3: Fahad Qureshi | C3: fahad.qureshi@yahoo.com | D3: 03482622631 | E3: Faisalabad | F3: Vacuum Cleaner | G3: Home Appliances | H3: 46244 | I3: 3 | J3: 85000 | K3: =I3*J3 -> 255000 | L3: Credit Card | M3: Active | N3: 46250
A4: ORD-1003 | B4: Waqas Ali | C4: waqas.ali@gmail.com | D4: 03207210606 | E4: FAISALABAD | F4: Headphones | G4: ELECTRONICS | H4: 46233 | I4: 3 | J4: 120000 | K4: =I4*J4 -> 360000 | L4: jazzcash | M4: ACTIVE | N4: 46238
A5: ORD-1004 | B5: Ayesha Iqbal | C5: AYESHA.IQBAL@HOTMAIL.COM | D5: 0372-6279418 | E5: PESHAWAR | F5: Bookshelf | G5: Furniture | H5: 46241 | I5: 5 | J5: 25000 | K5: =I5*J5 -> 125000 | L5: Bank Transfer | M5: active | N5: 46246
A6: ORD-1005 | B6: Zainab Ahmed | C6: zainab.ahmed@yahoo.com | D6: 03087455324 | E6: SIALKOT | F6: Vacuum Cleaner | G6: Home Appliances | H6: 46252 | I6: 3 | J6: 2500 | K6: =I6*J6 -> 7500 | L6: credit card | N6: 46256
A7: ORD-1006 | B7: Kashif Anwar | C7: kashif.anwar@gmail.com | D7: 0377-4337174 | E7: ISLAMABAD | F7: Microwave Oven | G7: Home Appliances | H7: 46227 | I7: 2 | J7: 1500 | K7: =I7*J7 -> 3000 | L7: Credit Card | M7: Active | N7: 46231
A8: ORD-1007 | B8: Bushra Ali | C8: bushra.ali@yahoo.com | D8: 0333 9852897 | E8: RAWALPINDI | F8: Study Table | G8: FURNITURE | H8: 46232 | I8: 4 | J8: 2500 | K8: =I8*J8 -> 10000 | L8: Credit Card | N8: 46238
A9: ORD-1008 | B9: Rida Iqbal | C9: rida.iqbal@gmail.com | D9: 0304-6543670 | E9: FAISALABAD | F9: Vacuum Cleaner | G9: Home Appliances | H9: 46219 | I9: 4 | J9: 8500 | K9: =I9*J9 -> 34000 | L9: cash | M9: Inactive | N9: 46224
A10: ORD-1009 | B10: Junaid Baig | C10: junaid.baig@gmail.com | D10: 0351-6692553 | E10: RAWALPINDI | F10: Sunglasses | G10: Accessories | H10: 46232 | I10: 1 | J10: 1500 | K10: =I10*J10 -> 1500 | L10: jazzcash | M10: Active | N10: 46238
A11: ORD-1010 | B11: Nida Sheikh | C11: nida.sheikh@outlook.com | D11: 03481036161 | E11: sialkot | F11: Vacuum Cleaner | G11: HOME APPLIANCES | H11: 46207 | I11: 5 | J11: 1500 | K11: =I11*J11 -> 7500 | L11: Bank Transfer | M11: inactive | N11: 46213
A12: ORD-1011 | B12: Anum Sheikh | C12: ANUM.SHEIKH@GMAIL.COM | D12: 0330-7774229 | E12: RAWALPINDI | F12: Water Dispenser | G12: Home Appliances | H12: 46220 | I12: 3 | J12: 8500 | K12: =I12*J12 -> 25500 | L12: credit card | M12: Pending | N12: 46223
A13: ORD-1012 | B13: Noor Farooq | C13: noor.farooq@gmail.com | D13: 0312 2229110 | E13: Faisalabad | F13: Headphones | G13: Electronics | H13: 46249 | I13: 5 | J13: 120000 | K13: =I13*J13 -> 600000 | M13: pending | N13: 46253
A14: ORD-1013 | B14: Usman Butt | C14: usman.butt@gmail.com | D14: 0326-6752576 | E14: FAISALABAD | F14: Mobile Phone | G14: Electronics | H14: 46225 | I14: 3 | J14: 4000 | K14: =I14*J14 -> 12000 | L14: JazzCash | M14: Inactive | N14: 46228
A15: ORD-1014 | B15: Mahnoor Ali | C15: mahnoor.ali@yahoo.com | E15: Multan | F15: Study Table | G15: FURNITURE | H15: 46230 | I15: 2 | J15: 8500 | K15: =I15*J15 -> 17000 | L15: CASH | M15: pending | N15: 46236
A16: ORD-1015 | B16: Junaid Khan | C16: junaid.khan@hotmail.com | D16: 03945163555 | E16: Karachi | F16: Blender | G16: Home Appliances | H16: 46254 | I16: 2 | J16: 1500 | K16: =I16*J16 -> 3000 | L16: Credit Card | M16: ACTIVE | N16: 46257
A17: ORD-1016 | B17: Rabia Javed | C17: rabia.javed@outlook.com | D17: 03032935113 | E17: Faisalabad | F17: Sunglasses | G17: accessories | H17: 46236 | I17: 4 | J17: 85000 | K17: =I17*J17 -> 340000 | L17: Credit Card | M17: Pending | N17: 46238
A18: ORD-1017 | B18: Anum Siddiqui | C18: ANUM.SIDDIQUI@YAHOO.COM | D18: 0342 6266630 | E18: FAISALABAD | F18: Sunglasses | G18: accessories | H18: 46230 | I18: 4 | J18: 120000 | K18: =I18*J18 -> 480000 | L18: CASH | M18: ACTIVE | N18: 46237
A19: ORD-1018 | B19: Ali Chaudhry | C19: ali.chaudhry@outlook.com | D19: 0356 8418210 | E19: SIALKOT | F19: Headphones | G19: electronics | H19: 46252 | I19: 3 | J19: 8500 | K19: =I19*J19 -> 25500 | L19: Credit Card | M19: Active | N19: 46255
A20: ORD-1019 | B20: Faisal Awan | C20: faisal.awan@gmail.com | D20: 03917442089 | E20: ISLAMABAD | F20: Smart Watch | G20: electronics | H20: 46233 | I20: 5 | J20: 8500 | K20: =I20*J20 -> 42500 | L20: cash | M20: pending | N20: 46235
A21: ORD-1020 | B21: Anum Siddiqui | C21: anum.siddiqui@outlook.com | D21: 0370-8481188 | E21: sialkot | F21: Sofa Set | G21: FURNITURE | H21: 46219 | I21: 4 | J21: 2500 | K21: =I21*J21 -> 10000 | L21: credit card | M21: ACTIVE | N21: 46223
A22: ORD-1021 | B22: Danish Ali | C22: danish.ali@yahoo.com | D22: 03537838382 | E22: Peshawar | F22: Sunglasses | G22: accessories | H22: 46252 | I22: 4 | J22: 45000 | K22: =I22*J22 -> 180000 | L22: Cash | M22: ACTIVE | N22: 46258
A23: ORD-1022 | B23: Junaid Siddiqui | C23: junaid.siddiqui@yahoo.com | D23: 0349 6639317 | E23: PESHAWAR | F23: Wrist Watch | G23: Accessories | H23: 46241 | I23: 1 | J23: 2500 | K23: =I23*J23 -> 2500 | L23: bank transfer | M23: Inactive | N23: 46247
A24: ORD-1023 | B24: Kashif Aslam | C24: kashif.aslam@outlook.com | D24: 03968072684 | E24: Sialkot | F24: Mobile Phone | G24: electronics | H24: 46206 | I24: 2 | J24: 8500 | K24: =I24*J24 -> 17000 | L24: Cash | M24: active | N24: 46208
A25: ORD-1024 | B25: Mahnoor Rana | C25: mahnoor.rana@outlook.com | D25: 0377-2921542 | E25: Karachi | F25: Air Fryer | G25: HOME APPLIANCES | H25: 46216 | I25: 5 | J25: 120000 | K25: =I25*J25 -> 600000 | L25: Credit Card | M25: pending | N25: 46218
A26: ORD-1025 | B26: Umar Malik | C26: umar.malik@gmail.com | D26: 0364-6724909 | E26: Sialkot | F26: Jacket | G26: APPAREL | H26: 46215 | I26: 5 | J26: 120000 | K26: =I26*J26 -> 600000 | L26: credit card | M26: inactive | N26: 46222
A27: ORD-1026 | B27: Noor Qureshi | C27: noor.qureshi@hotmail.com | D27: 0335-8563202 | F27: T-Shirt | G27: Apparel | H27: 46221 | I27: 3 | J27: 65000 | K27: =I27*J27 -> 195000 | L27: Cash | M27: active | N27: 46227
A28: ORD-1027 | B28: Junaid Abbasi | C28: junaid.abbasi@yahoo.com | D28: 03022561176 | E28: rawalpindi | F28: Jacket | G28: apparel | H28: 46239 | I28: 3 | J28: 45000 | K28: =I28*J28 -> 135000 | L28: credit card | M28: active | N28: 46243
A29: ORD-1028 | B29: Zeeshan Farooq | C29: zeeshan.farooq@yahoo.com | D29: 0375 9801946 | E29: karachi | F29: Jacket | G29: Apparel | H29: 46206 | I29: 5 | J29: 12000 | K29: =I29*J29 -> 60000 | L29: CASH | M29: pending | N29: 46208
A30: ORD-1072 | B30: Zeeshan Sheikh | D30: 03509479950 | E30: RAWALPINDI | F30: Mobile Phone | G30: electronics | H30: 46234 | I30: 5 | J30: 1500 | K30: =I30*J30 -> 7500 | L30: cash | M30: ACTIVE | N30: 46238
A31: ORD-1029 | B31: Ali Rana | C31: ali.rana@outlook.com | D31: 0361-2914064 | E31: Karachi | F31: Air Fryer | G31: home appliances | H31: 46230 | I31: 5 | J31: 85000 | K31: =I31*J31 -> 425000 | L31: Credit Card | M31: Inactive | N31: 46236
A32: ORD-1030 | B32: Asad Chaudhry | C32: asad.chaudhry@outlook.com | D32: 0394-2664863 | E32: FAISALABAD | F32: Sofa Set | G32: Furniture | H32: 46248 | I32: 4 | J32: 12000 | K32: =I32*J32 -> 48000 | L32: Cash | M32: Pending | N32: 46254
A33: ORD-1031 | B33: Noor Ali | C33: noor.ali@hotmail.com | D33: 0325-8132648 | E33: islamabad | F33: Headphones | G33: Electronics | H33: 46240 | I33: 4 | J33: 2500 | K33: =I33*J33 -> 10000 | L33: JazzCash | M33: Pending | N33: 46244
A34: ORD-1032 | B34: Rabia Anwar | C34: RABIA.ANWAR@OUTLOOK.COM | D34: 0341-5200476 | E34: LAHORE | F34: Office Chair | G34: furniture | H34: 46241 | I34: 4 | J34: 2500 | K34: =I34*J34 -> 10000 | L34: JazzCash | M34: ACTIVE | N34: 46246
A35: ORD-1033 | B35: Usman Sheikh | C35: usman.sheikh@outlook.com | D35: 03701615675 | E35: faisalabad | F35: Handbag | G35: ACCESSORIES | H35: 46233 | I35: 1 | J35: 8500 | K35: =I35*J35 -> 8500 | L35: jazzcash | M35: pending | N35: 46238
A36: ORD-1034 | B36: Asad Ahmed | C36: asad.ahmed@yahoo.com | D36: 0315 1484348 | E36: RAWALPINDI | F36: Vacuum Cleaner | G36: Home Appliances | H36: 46211 | I36: 1 | J36: 120000 | K36: =I36*J36 -> 120000 | L36: CASH | M36: Pending | N36: 46216
A37: ORD-1035 | B37: Rabia Qureshi | C37: rabia.qureshi@outlook.com | D37: 0376 9526867 | E37: KARACHI | F37: Sunglasses | G37: accessories | H37: 46222 | I37: 3 | J37: 85000 | K37: =I37*J37 -> 255000 | L37: Cash | M37: Inactive | N37: 46229
A38: ORD-1036 | B38: Asad Siddiqui | C38: asad.siddiqui@hotmail.com | D38: 0341 4165061 | E38: Peshawar | F38: Sunglasses | G38: Accessories | H38: 46228 | I38: 2 | J38: 45000 | K38: =I38*J38 -> 90000 | L38: Cash | M38: inactive | N38: 46233
A39: ORD-1037 | B39: Usman Baig | C39: usman.baig@outlook.com | D39: 03192255409 | E39: faisalabad | F39: Handbag | G39: ACCESSORIES | H39: 46238 | I39: 3 | J39: 120000 | K39: =I39*J39 -> 360000 | L39: JazzCash | M39: Active | N39: 46243
A40: ORD-1038 | B40: Nida Chaudhry | C40: nida.chaudhry@gmail.com | D40: 0312-8443690 | E40: Lahore | F40: Mobile Phone | G40: electronics | H40: 46230 | I40: 2 | J40: 4000 | K40: =I40*J40 -> 8000 | L40: CASH | M40: pending | N40: 46236
...

Sheet Pivot_Tables
A2: Row Labels | B2: Sum of Total_Sales | D2: Row Labels | E2: Sum of Total_Sales
A3: Home Appliances | B3: 4068500 | D3: Bank Transfer | E3: 1813000
A4: Accessories | B4: 3308000 | D4: Cash | E4: 3974000
A5: Electronics | B5: 2413000 | D5: Credit Card | E5: 4299500
A6: Furniture | B6: 2196500 | D6: JazzCash | E6: 2476500
A7: Apparel | B7: 1710500 | D7: Not Specified | E7: 1290000
A8: Unknown | B8: 156500 | D8: Grand Total | E8: 13853000
A9: Grand Total | B9: 13853000
A12: Row Labels | B12: Sum of Total_Sales | D12: Row Labels | E12: Sum of Total_Sales
A13: Faisalabad | B13: 3155500 | D13: 2026 | E13: 13853000
A14: Sialkot | B14: 2459000 | D14: Jul | E14: 7724500
A15: Rawalpindi | B15: 2043000 | D15: Aug | E15: 6128500
A16: Karachi | B16: 1695000 | D16: Grand Total | E16: 13853000
A17: Peshawar | B17: 1143500
A18: Islamabad | B18: 1061500
A19: Multan | B19: 1004500
A20: Unknown | B20: 813000
A21: Lahore | B21: 478000
A22: Grand Total | B22: 13853000

Sheet Dashboard
B3: Total Sales | D3: Total Orders | F3: Total Quantity | H3: Average Order Value
B4: =SUM(SalesData[Total_Sales]) -> 13853000 | D4: =COUNTA(SalesData[Order_ID]) -> 103 | F4: =SUM(SalesData[Quantity]) -> 323 | H4: =AVERAGE(SalesData[Total_Sales]) -> 134495.15

Sheet Sales_Dashboard

Sheet Cleaned_Data
A1: Order_ID | B1: Customer_Name | C1: Email | D1: Phone | E1: Phone_Cleaned | F1: City | G1: Product | H1: Category | I1: Order_Date | J1: Quantity | K1: Unit_Price | L1: Total_Sales | M1: Payment_Method | N1: Customer_Status | O1: Delivery_Date | P1: Order_Prefix (Left) | Q1: Order_Number (Right) | R1: Separator_Position | S1: MID_Number
A2: ORD-1012 | B2: =CLEAN(TRIM(Raw_Data!B13)) -> Noor Farooq | C2: noor.farooq@gmail.com | D2: 0312 2229110 | E2: =SUBSTITUTE(SUBSTITUTE(D2,"-","")," ","") -> 03122229110 | F2: =TRIM(PROPER(Raw_Data!E13)) -> Faisalabad | G2: =TRIM(PROPER(Raw_Data!F13)) -> Headphones | H2: =TRIM(PROPER(Raw_Data!G13)) -> Electronics | I2: 46249 | J2: 5 | K2: 120000 | L2: =J2*K2 -> 600000 | M2: Not Specified | N2: Pending | O2: 46253 | P2: =LEFT(A2,3) -> ORD | Q2: =RIGHT(A2,4) -> 1012 | R2: =FIND("-",A2) -> 4 | S2: =MID(A2,FIND("-",A2)+1,4) -> 1012
A3: ORD-1024 | B3: =CLEAN(TRIM(Raw_Data!B25)) -> Mahnoor Rana | C3: mahnoor.rana@outlook.com | D3: 0377-2921542 | E3: =SUBSTITUTE(SUBSTITUTE(D3,"-","")," ","") -> 03772921542 | F3: =TRIM(PROPER(Raw_Data!E25)) -> Karachi | G3: =TRIM(PROPER(Raw_Data!F25)) -> Air Fryer | H3: =TRIM(PROPER(Raw_Data!G25)) -> Home Appliances | I3: 46216 | J3: 5 | K3: 120000 | L3: =J3*K3 -> 600000 | M3: Credit Card | N3: Pending | O3: 46218 | P3: =LEFT(A3,3) -> ORD | Q3: =RIGHT(A3,4) -> 1024 | R3: =FIND("-",A3) -> 4 | S3: =MID(A3,FIND("-",A3)+1,4) -> 1024
A4: ORD-1025 | B4: =CLEAN(TRIM(Raw_Data!B26)) -> Umar Malik | C4: umar.malik@gmail.com | D4: 0364-6724909 | E4: =SUBSTITUTE(SUBSTITUTE(D4,"-","")," ","") -> 03646724909 | F4: =TRIM(PROPER(Raw_Data!E26)) -> Sialkot | G4: =TRIM(PROPER(Raw_Data!F26)) -> Jacket | H4: =TRIM(PROPER(Raw_Data!G26)) -> Apparel | I4: 46215 | J4: 5 | K4: 120000 | L4: =J4*K4 -> 600000 | M4: Credit Card | N4: InActive | O4: 46222 | P4: =LEFT(A4,3) -> ORD | Q4: =RIGHT(A4,4) -> 1025 | R4: =FIND("-",A4) -> 4 | S4: =MID(A4,FIND("-",A4)+1,4) -> 1025
A5: ORD-1049 | B5: =CLEAN(TRIM(Raw_Data!B52)) -> Faisal Iqbal | C5: faisal.iqbal@hotmail.com | D5: 03734794319 | E5: =SUBSTITUTE(SUBSTITUTE(D5,"-","")," ","") -> 03734794319 | F5: Unknown | G5: =TRIM(PROPER(Raw_Data!F52)) -> Bookshelf | H5: Furniture | I5: 46215 | J5: 5 | K5: 120000 | L5: =J5*K5 -> 600000 | M5: Bank Transfer | N5: Pending | O5: 46218 | P5: =LEFT(A5,3) -> ORD | Q5: =RIGHT(A5,4) -> 1049 | R5: =FIND("-",A5) -> 4 | S5: =MID(A5,FIND("-",A5)+1,4) -> 1049
A6: ORD-1080 | B6: =CLEAN(TRIM(Raw_Data!B85)) -> Umar Malik | C6: umar.malik@hotmail.com | D6: 0363 3251501 | E6: =SUBSTITUTE(SUBSTITUTE(D6,"-","")," ","") -> 03633251501 | F6: =TRIM(PROPER(Raw_Data!E85)) -> Rawalpindi | G6: =TRIM(PROPER(Raw_Data!F85)) -> Wrist Watch | H6: Accessories | I6: 46254 | J6: 5 | K6: 120000 | L6: =J6*K6 -> 600000 | M6: Credit Card | N6: Pending | O6: 46258 | P6: =LEFT(A6,3) -> ORD | Q6: =RIGHT(A6,4) -> 1080 | R6: =FIND("-",A6) -> 4 | S6: =MID(A6,FIND("-",A6)+1,4) -> 1080
A7: ORD-1017 | B7: =CLEAN(TRIM(Raw_Data!B18)) -> Anum Siddiqui | C7: anum.siddiqui@yahoo.com | D7: 0342 6266630 | E7: =SUBSTITUTE(SUBSTITUTE(D7,"-","")," ","") -> 03426266630 | F7: =TRIM(PROPER(Raw_Data!E18)) -> Faisalabad | G7: =TRIM(PROPER(Raw_Data!F18)) -> Sunglasses | H7: =TRIM(PROPER(Raw_Data!G18)) -> Accessories | I7: 46230 | J7: 4 | K7: 120000 | L7: =J7*K7 -> 480000 | M7: Cash | N7: Active | O7: 46237 | P7: =LEFT(A7,3) -> ORD | Q7: =RIGHT(A7,4) -> 1017 | R7: =FIND("-",A7) -> 4 | S7: =MID(A7,FIND("-",A7)+1,4) -> 1017
A8: ORD-1083 | B8: =CLEAN(TRIM(Raw_Data!B88)) -> Naveed Malik | C8: naveed.malik@yahoo.com | D8: 0366-8412854 | E8: =SUBSTITUTE(SUBSTITUTE(D8,"-","")," ","") -> 03668412854 | F8: =TRIM(PROPER(Raw_Data!E88)) -> Sialkot | G8: =TRIM(PROPER(Raw_Data!F88)) -> Wrist Watch | H8: Accessories | I8: 46207 | J8: 4 | K8: 120000 | L8: =J8*K8 -> 480000 | M8: Credit Card | N8: InActive | O8: 46213 | P8: =LEFT(A8,3) -> ORD | Q8: =RIGHT(A8,4) -> 1083 | R8: =FIND("-",A8) -> 4 | S8: =MID(A8,FIND("-",A8)+1,4) -> 1083
A9: ORD-1091 | B9: =CLEAN(TRIM(Raw_Data!B96)) -> Danish Abbasi | C9: danish.abbasi@gmail.com | D9: 0385-1813936 | E9: =SUBSTITUTE(SUBSTITUTE(D9,"-","")," ","") -> 03851813936 | F9: =TRIM(PROPER(Raw_Data!E96)) -> Rawalpindi | G9: =TRIM(PROPER(Raw_Data!F96)) -> Laptop | H9: Electronics | I9: 46246 | J9: 4 | K9: 120000 | L9: =J9*K9 -> 480000 | M9: Not Specified | N9: InActive | O9: 46252 | P9: =LEFT(A9,3) -> ORD | Q9: =RIGHT(A9,4) -> 1091 | R9: =FIND("-",A9) -> 4 | S9: =MID(A9,FIND("-",A9)+1,4) -> 1091
A10: ORD-1029 | B10: =CLEAN(TRIM(Raw_Data!B31)) -> Ali Rana | C10: ali.rana@outlook.com | D10: 0361-2914064 | E10: =SUBSTITUTE(SUBSTITUTE(D10,"-","")," ","") -> 03612914064 | F10: =TRIM(PROPER(Raw_Data!E31)) -> Karachi | G10: =TRIM(PROPER(Raw_Data!F31)) -> Air Fryer | H10: =TRIM(PROPER(Raw_Data!G31)) -> Home Appliances | I10: 46230 | J10: 5 | K10: 85000 | L10: =J10*K10 -> 425000 | M10: Credit Card | N10: InActive | O10: 46236 | P10: =LEFT(A10,3) -> ORD | Q10: =RIGHT(A10,4) -> 1029 | R10: =FIND("-",A10) -> 4 | S10: =MID(A10,FIND("-",A10)+1,4) -> 1029
A11: ORD-1060 | B11: =CLEAN(TRIM(Raw_Data!B64)) -> Zainab Javed | C11: zainab.javed@hotmail.com | D11: 0318-3308538 | E11: =SUBSTITUTE(SUBSTITUTE(D11,"-","")," ","") -> 03183308538 | F11: =TRIM(PROPER(Raw_Data!E64)) -> Sialkot | G11: =TRIM(PROPER(Raw_Data!F64)) -> Blender | H11: Home Appliances | I11: 46217 | J11: 5 | K11: 85000 | L11: =J11*K11 -> 425000 | M11: JazzCash | N11: Pending | O11: 46220 | P11: =LEFT(A11,3) -> ORD | Q11: =RIGHT(A11,4) -> 1060 | R11: =FIND("-",A11) -> 4 | S11: =MID(A11,FIND("-",A11)+1,4) -> 1060
A12: ORD-1003 | B12: =CLEAN(TRIM(Raw_Data!B4)) -> Waqas Ali | C12: waqas.ali@gmail.com | D12: 03207210606 | E12: =SUBSTITUTE(SUBSTITUTE(D12,"-","")," ","") -> 03207210606 | F12: =TRIM(PROPER(Raw_Data!E4)) -> Faisalabad | G12: =TRIM(PROPER(Raw_Data!F4)) -> Headphones | H12: =TRIM(PROPER(Raw_Data!G4)) -> Electronics | I12: 46233 | J12: 3 | K12: 120000 | L12: =J12*K12 -> 360000 | M12: JazzCash | N12: Active | O12: 46238 | P12: =LEFT(A12,3) -> ORD | Q12: =RIGHT(A12,4) -> 1003 | R12: =FIND("-",A12) -> 4 | S12: =MID(A12,FIND("-",A12)+1,4) -> 1003
A13: ORD-1037 | B13: =CLEAN(TRIM(Raw_Data!B39)) -> Usman Baig | C13: usman.baig@outlook.com | D13: 03192255409 | E13: =SUBSTITUTE(SUBSTITUTE(D13,"-","")," ","") -> 03192255409 | F13: =TRIM(PROPER(Raw_Data!E39)) -> Faisalabad | G13: =TRIM(PROPER(Raw_Data!F39)) -> Handbag | H13: =TRIM(PROPER(Raw_Data!G39)) -> Accessories | I13: 46238 | J13: 3 | K13: 120000 | L13: =J13*K13 -> 360000 | M13: JazzCash | N13: Active | O13: 46243 | P13: =LEFT(A13,3) -> ORD | Q13: =RIGHT(A13,4) -> 1037 | R13: =FIND("-",A13) -> 4 | S13: =MID(A13,FIND("-",A13)+1,4) -> 1037
A14: ORD-1016 | B14: =CLEAN(TRIM(Raw_Data!B17)) -> Rabia Javed | C14: rabia.javed@outlook.com | D14: 03032935113 | E14: =SUBSTITUTE(SUBSTITUTE(D14,"-","")," ","") -> 03032935113 | F14: =TRIM(PROPER(Raw_Data!E17)) -> Faisalabad | G14: =TRIM(PROPER(Raw_Data!F17)) -> Sunglasses | H14: =TRIM(PROPER(Raw_Data!G17)) -> Accessories | I14: 46236 | J14: 4 | K14: 85000 | L14: =J14*K14 -> 340000 | M14: Credit Card | N14: Pending | O14: 46238 | P14: =LEFT(A14,3) -> ORD | Q14: =RIGHT(A14,4) -> 1016 | R14: =FIND("-",A14) -> 4 | S14: =MID(A14,FIND("-",A14)+1,4) -> 1016
A15: ORD-1043 | B15: =CLEAN(TRIM(Raw_Data!B45)) -> Hira Qureshi | C15: hira.qureshi@gmail.com | D15: 0312 4939290 | E15: =SUBSTITUTE(SUBSTITUTE(D15,"-","")," ","") -> 03124939290 | F15: =TRIM(PROPER(Raw_Data!E45)) -> Sialkot | G15: =TRIM(PROPER(Raw_Data!F45)) -> Vacuum Cleaner | H15: =TRIM(PROPER(Raw_Data!G45)) -> Home Appliances | I15: 46245 | J15: 4 | K15: 85000 | L15: =J15*K15 -> 340000 | M15: Bank Transfer | N15: Unknown | O15: 46247 | P15: =LEFT(A15,3) -> ORD | Q15: =RIGHT(A15,4) -> 1043 | R15: =FIND("-",A15) -> 4 | S15: =MID(A15,FIND("-",A15)+1,4) -> 1043
A16: ORD-1064 | B16: =CLEAN(TRIM(Raw_Data!B68)) -> Imran Farooq | C16: imran.farooq@outlook.com | D16: 0334 2385991 | E16: =SUBSTITUTE(SUBSTITUTE(D16,"-","")," ","") -> 03342385991 | F16: =TRIM(PROPER(Raw_Data!E68)) -> Peshawar | G16: =TRIM(PROPER(Raw_Data!F68)) -> Office Chair | H16: Furniture | I16: 46222 | J16: 4 | K16: 85000 | L16: =J16*K16 -> 340000 | M16: Bank Transfer | N16: InActive | O16: 46226 | P16: =LEFT(A16,3) -> ORD | Q16: =RIGHT(A16,4) -> 1064 | R16: =FIND("-",A16) -> 4 | S16: =MID(A16,FIND("-",A16)+1,4) -> 1064
A17: ORD-1074 | B17: =CLEAN(TRIM(Raw_Data!B79)) -> Hamza Ahmed | C17: hamza.ahmed@hotmail.com | D17: 03653345135 | E17: =SUBSTITUTE(SUBSTITUTE(D17,"-","")," ","") -> 03653345135 | F17: =TRIM(PROPER(Raw_Data!E79)) -> Multan | G17: =TRIM(PROPER(Raw_Data!F79)) -> Water Dispenser | H17: Home Appliances | I17: 46236 | J17: 4 | K17: 85000 | L17: =J17*K17 -> 340000 | M17: Credit Card | N17: Active | O17: 46242 | P17: =LEFT(A17,3) -> ORD | Q17: =RIGHT(A17,4) -> 1074 | R17: =FIND("-",A17) -> 4 | S17: =MID(A17,FIND("-",A17)+1,4) -> 1074
A18: ORD-1097 | B18: =CLEAN(TRIM(Raw_Data!B102)) -> Zainab Siddiqui | C18: zainab.siddiqui@yahoo.com | D18: 03175511711 | E18: =SUBSTITUTE(SUBSTITUTE(D18,"-","")," ","") -> 03175511711 | F18: =TRIM(PROPER(Raw_Data!E102)) -> Islamabad | G18: =TRIM(PROPER(Raw_Data!F102)) -> Bookshelf | H18: Furniture | I18: 46219 | J18: 4 | K18: 85000 | L18: =J18*K18 -> 340000 | M18: Cash | N18: Active | O18: 46226 | P18: =LEFT(A18,3) -> ORD | Q18: =RIGHT(A18,4) -> 1097 | R18: =FIND("-",A18) -> 4 | S18: =MID(A18,FIND("-",A18)+1,4) -> 1097
A19: ORD-1058 | B19: =CLEAN(TRIM(Raw_Data!B62)) -> Warda Sheikh | C19: warda.sheikh@gmail.com | D19: 0356 5780297 | E19: =SUBSTITUTE(SUBSTITUTE(D19,"-","")," ","") -> 03565780297 | F19: =TRIM(PROPER(Raw_Data!E62)) -> Rawalpindi | G19: =TRIM(PROPER(Raw_Data!F62)) -> Blender | H19: Home Appliances | I19: 46233 | J19: 4 | K19: 65000 | L19: =J19*K19 -> 260000 | M19: JazzCash | N19: Active | O19: 46237 | P19: =LEFT(A19,3) -> ORD | Q19: =RIGHT(A19,4) -> 1058 | R19: =FIND("-",A19) -> 4 | S19: =MID(A19,FIND("-",A19)+1,4) -> 1058
A20: ORD-1068 | B20: =CLEAN(TRIM(Raw_Data!B72)) -> Zainab Ali | C20: zainab.ali@outlook.com | D20: 03093102634 | E20: =SUBSTITUTE(SUBSTITUTE(D20,"-","")," ","") -> 03093102634 | F20: =TRIM(PROPER(Raw_Data!E72)) -> Sialkot | G20: =TRIM(PROPER(Raw_Data!F72)) -> Jacket | H20: Apparel | I20: 46215 | J20: 4 | K20: 65000 | L20: =J20*K20 -> 260000 | M20: Cash | N20: InActive | O20: 46218 | P20: =LEFT(A20,3) -> ORD | Q20: =RIGHT(A20,4) -> 1068 | R20: =FIND("-",A20) -> 4 | S20: =MID(A20,FIND("-",A20)+1,4) -> 1068
A21: ORD-1002 | B21: =CLEAN(TRIM(Raw_Data!B3)) -> Fahad Qureshi | C21: fahad.qureshi@yahoo.com | D21: 03482622631 | E21: =SUBSTITUTE(SUBSTITUTE(D21,"-","")," ","") -> 03482622631 | F21: =TRIM(PROPER(Raw_Data!E3)) -> Faisalabad | G21: =TRIM(PROPER(Raw_Data!F3)) -> Vacuum Cleaner | H21: =TRIM(PROPER(Raw_Data!G3)) -> Home Appliances | I21: 46244 | J21: 3 | K21: 85000 | L21: =J21*K21 -> 255000 | M21: Credit Card | N21: Active | O21: 46250 | P21: =LEFT(A21,3) -> ORD | Q21: =RIGHT(A21,4) -> 1002 | R21: =FIND("-",A21) -> 4 | S21: =MID(A21,FIND("-",A21)+1,4) -> 1002
A22: ORD-1035 | B22: =CLEAN(TRIM(Raw_Data!B37)) -> Rabia Qureshi | C22: rabia.qureshi@outlook.com | D22: 0376 9526867 | E22: =SUBSTITUTE(SUBSTITUTE(D22,"-","")," ","") -> 03769526867 | F22: =TRIM(PROPER(Raw_Data!E37)) -> Karachi | G22: =TRIM(PROPER(Raw_Data!F37)) -> Sunglasses | H22: =TRIM(PROPER(Raw_Data!G37)) -> Accessories | I22: 46222 | J22: 3 | K22: 85000 | L22: =J22*K22 -> 255000 | M22: Cash | N22: InActive | O22: 46229 | P22: =LEFT(A22,3) -> ORD | Q22: =RIGHT(A22,4) -> 1035 | R22: =FIND("-",A22) -> 4 | S22: =MID(A22,FIND("-",A22)+1,4) -> 1035
A23: ORD-1057 | B23: =CLEAN(TRIM(Raw_Data!B61)) -> Hassan Anwar | C23: hassan.anwar@outlook.com | D23: 03276733317 | E23: =SUBSTITUTE(SUBSTITUTE(D23,"-","")," ","") -> 03276733317 | F23: =TRIM(PROPER(Raw_Data!E61)) -> Islamabad | G23: =TRIM(PROPER(Raw_Data!F61)) -> Smart Watch | H23: Electronics | I23: 46206 | J23: 3 | K23: 85000 | L23: =J23*K23 -> 255000 | M23: Cash | N23: Active | O23: 46213 | P23: =LEFT(A23,3) -> ORD | Q23: =RIGHT(A23,4) -> 1057 | R23: =FIND("-",A23) -> 4 | S23: =MID(A23,FIND("-",A23)+1,4) -> 1057
A24: ORD-1076 | B24: =CLEAN(TRIM(Raw_Data!B81)) -> Iqra Qureshi | C24: iqra.qureshi@outlook.com | D24: 0317-9702060 | E24: =SUBSTITUTE(SUBSTITUTE(D24,"-","")," ","") -> 03179702060 | F24: =TRIM(PROPER(Raw_Data!E81)) -> Sialkot | G24: =TRIM(PROPER(Raw_Data!F81)) -> Office Chair | H24: Furniture | I24: 46253 | J24: 3 | K24: 85000 | L24: =J24*K24 -> 255000 | M24: JazzCash | N24: Active | O24: 46260 | P24: =LEFT(A24,3) -> ORD | Q24: =RIGHT(A24,4) -> 1076 | R24: =FIND("-",A24) -> 4 | S24: =MID(A24,FIND("-",A24)+1,4) -> 1076
A25: ORD-1040 | B25: =CLEAN(TRIM(Raw_Data!B42)) -> Naveed Chaudhry | C25: naveed.chaudhry@hotmail.com | D25: 0301 1822825 | E25: =SUBSTITUTE(SUBSTITUTE(D25,"-","")," ","") -> 03011822825 | F25: =TRIM(PROPER(Raw_Data!E42)) -> Faisalabad | G25: =TRIM(PROPER(Raw_Data!F42)) -> Jacket | H25: =TRIM(PROPER(Raw_Data!G42)) -> Apparel | I25: 46250 | J25: 2 | K25: 120000 | L25: =J25*K25 -> 240000 | M25: Cash | N25: Unknown | O25: 46257 | P25: =LEFT(A25,3) -> ORD | Q25: =RIGHT(A25,4) -> 1040 | R25: =FIND("-",A25) -> 4 | S25: =MID(A25,FIND("-",A25)+1,4) -> 1040
A26: ORD-1062 | B26: =CLEAN(TRIM(Raw_Data!B66)) -> Salman Siddiqui | C26: salman.siddiqui@outlook.com | D26: 03951272499 | E26: =SUBSTITUTE(SUBSTITUTE(D26,"-","")," ","") -> 03951272499 | F26: =TRIM(PROPER(Raw_Data!E66)) -> Multan | G26: =TRIM(PROPER(Raw_Data!F66)) -> Smart Watch | H26: Electronics | I26: 46238 | J26: 2 | K26: 120000 | L26: =J26*K26 -> 240000 | M26: JazzCash | N26: InActive | O26: 46242 | P26: =LEFT(A26,3) -> ORD | Q26: =RIGHT(A26,4) -> 1062 | R26: =FIND("-",A26) -> 4 | S26: =MID(A26,FIND("-",A26)+1,4) -> 1062
A27: ORD-1069 | B27: =CLEAN(TRIM(Raw_Data!B73)) -> Fahad Sheikh | C27: fahad.sheikh@yahoo.com | D27: 0310-5204459 | E27: =SUBSTITUTE(SUBSTITUTE(D27,"-","")," ","") -> 03105204459 | F27: =TRIM(PROPER(Raw_Data!E73)) -> Faisalabad | G27: =TRIM(PROPER(Raw_Data!F73)) -> Water Dispenser | H27: Home Appliances | I27: 46241 | J27: 2 | K27: 120000 | L27: =J27*K27 -> 240000 | M27: Cash | N27: InActive | O27: 46244 | P27: =LEFT(A27,3) -> ORD | Q27: =RIGHT(A27,4) -> 1069 | R27: =FIND("-",A27) -> 4 | S27: =MID(A27,FIND("-",A27)+1,4) -> 1069
A28: ORD-1026 | B28: =CLEAN(TRIM(Raw_Data!B27)) -> Noor Qureshi | C28: noor.qureshi@hotmail.com | D28: 0335-8563202 | E28: =SUBSTITUTE(SUBSTITUTE(D28,"-","")," ","") -> 03358563202 | F28: Unknown | G28: =TRIM(PROPER(Raw_Data!F27)) -> T-Shirt | H28: =TRIM(PROPER(Raw_Data!G27)) -> Apparel | I28: 46221 | J28: 3 | K28: 65000 | L28: =J28*K28 -> 195000 | M28: Cash | N28: Active | O28: 46227 | P28: =LEFT(A28,3) -> ORD | Q28: =RIGHT(A28,4) -> 1026 | R28: =FIND("-",A28) -> 4 | S28: =MID(A28,FIND("-",A28)+1,4) -> 1026
A29: ORD-1021 | B29: =CLEAN(TRIM(Raw_Data!B22)) -> Danish Ali | C29: danish.ali@yahoo.com | D29: 03537838382 | E29: =SUBSTITUTE(SUBSTITUTE(D29,"-","")," ","") -> 03537838382 | F29: =TRIM(PROPER(Raw_Data!E22)) -> Peshawar | G29: =TRIM(PROPER(Raw_Data!F22)) -> Sunglasses | H29: =TRIM(PROPER(Raw_Data!G22)) -> Accessories | I29: 46252 | J29: 4 | K29: 45000 | L29: =J29*K29 -> 180000 | M29: Cash | N29: Active | O29: 46258 | P29: =LEFT(A29,3) -> ORD | Q29: =RIGHT(A29,4) -> 1021 | R29: =FIND("-",A29) -> 4 | S29: =MID(A29,FIND("-",A29)+1,4) -> 1021
A30: ORD-1090 | B30: =CLEAN(TRIM(Raw_Data!B95)) -> Hamza Rana | C30: hamza.rana@yahoo.com | D30: 03928005797 | E30: =SUBSTITUTE(SUBSTITUTE(D30,"-","")," ","") -> 03928005797 | F30: =TRIM(PROPER(Raw_Data!E95)) -> Multan | G30: =TRIM(PROPER(Raw_Data!F95)) -> Sofa Set | H30: Furniture | I30: 46252 | J30: 4 | K30: 45000 | L30: =J30*K30 -> 180000 | M30: Cash | N30: Active | O30: 46257 | P30: =LEFT(A30,3) -> ORD | Q30: =RIGHT(A30,4) -> 1090 | R30: =FIND("-",A30) -> 4 | S30: =MID(A30,FIND("-",A30)+1,4) -> 1090
A31: ORD-1092 | B31: =CLEAN(TRIM(Raw_Data!B97)) -> Ali Khan | C31: ali.khan@hotmail.com | D31: 0389-8223819 | E31: =SUBSTITUTE(SUBSTITUTE(D31,"-","")," ","") -> 03898223819 | F31: =TRIM(PROPER(Raw_Data!E97)) -> Karachi | G31: =TRIM(PROPER(Raw_Data!F97)) -> Water Dispenser | H31: Home Appliances | I31: 46209 | J31: 4 | K31: 45000 | L31: =J31*K31 -> 180000 | M31: Cash | N31: Pending | O31: 46213 | P31: =LEFT(A31,3) -> ORD | Q31: =RIGHT(A31,4) -> 1092 | R31: =FIND("-",A31) -> 4 | S31: =MID(A31,FIND("-",A31)+1,4) -> 1092
A32: ORD-1027 | B32: =CLEAN(TRIM(Raw_Data!B28)) -> Junaid Abbasi | C32: junaid.abbasi@yahoo.com | D32: 03022561176 | E32: =SUBSTITUTE(SUBSTITUTE(D32,"-","")," ","") -> 03022561176 | F32: =TRIM(PROPER(Raw_Data!E28)) -> Rawalpindi | G32: =TRIM(PROPER(Raw_Data!F28)) -> Jacket | H32: =TRIM(PROPER(Raw_Data!G28)) -> Apparel | I32: 46239 | J32: 3 | K32: 45000 | L32: =J32*K32 -> 135000 | M32: Credit Card | N32: Active | O32: 46243 | P32: =LEFT(A32,3) -> ORD | Q32: =RIGHT(A32,4) -> 1027 | R32: =FIND("-",A32) -> 4 | S32: =MID(A32,FIND("-",A32)+1,4) -> 1027
A33: ORD-1066 | B33: =CLEAN(TRIM(Raw_Data!B70)) -> Asad Javed | C33: asad.javed@gmail.com | D33: 0383-5675638 | E33: =SUBSTITUTE(SUBSTITUTE(D33,"-","")," ","") -> 03835675638 | F33: =TRIM(PROPER(Raw_Data!E70)) -> Lahore | G33: =TRIM(PROPER(Raw_Data!F70)) -> Handbag | H33: Accessories | I33: 46217 | J33: 3 | K33: 45000 | L33: =J33*K33 -> 135000 | M33: Credit Card | N33: Pending | O33: 46223 | P33: =LEFT(A33,3) -> ORD | Q33: =RIGHT(A33,4) -> 1066 | R33: =FIND("-",A33) -> 4 | S33: =MID(A33,FIND("-",A33)+1,4) -> 1066
A34: ORD-1070 | B34: =CLEAN(TRIM(Raw_Data!B74)) -> Naveed Ahmed | C34: naveed.ahmed@gmail.com | D34: 0333 4536777 | E34: =SUBSTITUTE(SUBSTITUTE(D34,"-","")," ","") -> 03334536777 | F34: =TRIM(PROPER(Raw_Data!E74)) -> Lahore | G34: =TRIM(PROPER(Raw_Data!F74)) -> Vacuum Cleaner | H34: Home Appliances | I34: 46247 | J34: 3 | K34: 45000 | L34: =J34*K34 -> 135000 | M34: Cash | N34: Active | O34: 46252 | P34: =LEFT(A34,3) -> ORD | Q34: =RIGHT(A34,4) -> 1070 | R34: =FIND("-",A34) -> 4 | S34: =MID(A34,FIND("-",A34)+1,4) -> 1070
A35: ORD-1004 | B35: =CLEAN(TRIM(Raw_Data!B5)) -> Ayesha Iqbal | C35: ayesha.iqbal@hotmail.com | D35: 0372-6279418 | E35: =SUBSTITUTE(SUBSTITUTE(D35,"-","")," ","") -> 03726279418 | F35: =TRIM(PROPER(Raw_Data!E5)) -> Peshawar | G35: =TRIM(PROPER(Raw_Data!F5)) -> Bookshelf | H35: =TRIM(PROPER(Raw_Data!G5)) -> Furniture | I35: 46241 | J35: 5 | K35: 25000 | L35: =J35*K35 -> 125000 | M35: Bank Transfer | N35: Active | O35: 46246 | P35: =LEFT(A35,3) -> ORD | Q35: =RIGHT(A35,4) -> 1004 | R35: =FIND("-",A35) -> 4 | S35: =MID(A35,FIND("-",A35)+1,4) -> 1004
A36: ORD-1034 | B36: =CLEAN(TRIM(Raw_Data!B36)) -> Asad Ahmed | C36: asad.ahmed@yahoo.com | D36: 0315 1484348 | E36: =SUBSTITUTE(SUBSTITUTE(D36,"-","")," ","") -> 03151484348 | F36: =TRIM(PROPER(Raw_Data!E36)) -> Rawalpindi | G36: =TRIM(PROPER(Raw_Data!F36)) -> Vacuum Cleaner | H36: =TRIM(PROPER(Raw_Data!G36)) -> Home Appliances | I36: 46211 | J36: 1 | K36: 120000 | L36: =J36*K36 -> 120000 | M36: Cash | N36: Pending | O36: 46216 | P36: =LEFT(A36,3) -> ORD | Q36: =RIGHT(A36,4) -> 1034 | R36: =FIND("-",A36) -> 4 | S36: =MID(A36,FIND("-",A36)+1,4) -> 1034
A37: ORD-1078 | B37: =CLEAN(TRIM(Raw_Data!B83)) -> Asad Hussain | C37: asad.hussain@yahoo.com | D37: 0389-5557052 | E37: =SUBSTITUTE(SUBSTITUTE(D37,"-","")," ","") -> 03895557052 | F37: =TRIM(PROPER(Raw_Data!E83)) -> Rawalpindi | G37: =TRIM(PROPER(Raw_Data!F83)) -> Microwave Oven | H37: Home Appliances | I37: 46249 | J37: 1 | K37: 120000 | L37: =J37*K37 -> 120000 | M37: Not Specified | N37: InActive | O37: 46254 | P37: =LEFT(A37,3) -> ORD | Q37: =RIGHT(A37,4) -> 1078 | R37: =FIND("-",A37) -> 4 | S37: =MID(A37,FIND("-",A37)+1,4) -> 1078
A38: ORD-1084 | B38: =CLEAN(TRIM(Raw_Data!B89)) -> Ali Raza | C38: ali.raza@gmail.com | D38: Not Provided | E38: =SUBSTITUTE(SUBSTITUTE(D38,"-","")," ","") -> NotProvided | F38: =TRIM(PROPER(Raw_Data!E89)) -> Peshawar | G38: =TRIM(PROPER(Raw_Data!F89)) -> Sunglasses | H38: Accessories | I38: 46228 | J38: 1 | K38: 120000 | L38: =J38*K38 -> 120000 | M38: JazzCash | N38: Pending | O38: 46233 | P38: =LEFT(A38,3) -> ORD | Q38: =RIGHT(A38,4) -> 1084 | R38: =FIND("-",A38) -> 4 | S38: =MID(A38,FIND("-",A38)+1,4) -> 1084
A39: ORD-1085 | B39: =CLEAN(TRIM(Raw_Data!B90)) -> Amna Siddiqui | C39: Not Provided | D39: 3026005700 | E39: =SUBSTITUTE(SUBSTITUTE(D39,"-","")," ","") -> 3026005700 | F39: =TRIM(PROPER(Raw_Data!E90)) -> Peshawar | G39: =TRIM(PROPER(Raw_Data!F90)) -> Sofa Set | H39: Furniture | I39: 46250 | J39: 1 | K39: 120000 | L39: =J39*K39 -> 120000 | M39: Bank Transfer | N39: Active | O39: 46252 | P39: =LEFT(A39,3) -> ORD | Q39: =RIGHT(A39,4) -> 1085 | R39: =FIND("-",A39) -> 4 | S39: =MID(A39,FIND("-",A39)+1,4) -> 1085
A40: ORD-1050 | B40: =CLEAN(TRIM(Raw_Data!B53)) -> Sara Ali | C40: sara.ali@yahoo.com | D40: 0339 6442241 | E40: =SUBSTITUTE(SUBSTITUTE(D40,"-","")," ","") -> 03396442241 | F40: =TRIM(PROPER(Raw_Data!E53)) -> Lahore | G40: =TRIM(PROPER(Raw_Data!F53)) -> Water Dispenser | H40: Home Appliances | I40: 46235 | J40: 4 | K40: 25000 | L40: =J40*K40 -> 100000 | M40: Credit Card | N40: InActive | O40: 46241 | P40: =LEFT(A40,3) -> ORD | Q40: =RIGHT(A40,4) -> 1050 | R40: =FIND("-",A40) -> 4 | S40: =MID(A40,FIND("-",A40)+1,4) -> 1050
...
